Workbook

Sheet Inputs
A1: VESLA ERP — Cloud Cost Projection (Neon + Render)
A2: Yellow cells = editable inputs. Change them and all calculations update automatically.
A4: COMPANY ASSUMPTIONS
A5: Parameter | B5: Value | E5: Notes
A6: Number of companies | B6: 5 | E6: Total tenant count
A7: Vehicles per company | B7: 200 | E7: Medium fleet = 100-300
A8: Concurrent users per company (peak) | B8: 20 | E8: Staff on system during business hours
A9: Active contracts per company/month | B9: 500 | E9: Bookings + rentals
A10: Invoices per company/month | B10: 500 | E10: Billing events
A11: TARS fines per company/month | B11: 200 | E11: Traffic fines processed
A12: Employees per company (HR) | B12: 50 | E12: HR/payroll records
A13: Customers per company | B13: 2000 | E13: Growing customer base
A15: USAGE PATTERN
A16: Parameter | B16: Value | C16: Unit | E16: Notes
A17: Business hours per day | B17: 14 | C17: hours | E17: Typical UAE: 8am-10pm
A18: Days per month | B18: 30 | C18: days | E18: Calendar month
A19: Off-peak hours per day | B19: 10 | C19: hours | E19: =24 minus business hours
A20: Weekend/holiday reduction | B20: 0.3 | E20: 30% less traffic on weekends
A22: NEON PRICING (from neon.com/docs — Aug 2025 model)
A23: Parameter | B23: Launch Plan | C23: Scale Plan | E23: Source
A24: Compute rate (per CU-hour) | B24: 0.106 | C24: 0.222 | E24: neon.com/docs/introduction/plans
A25: Storage rate (per GB-month) | B25: 0.35 | C25: 0.35 | E25: Same on both plans
A26: Instant Restore (per GB-month) | B26: 0.2 | C26: 0.2 | E26: For point-in-time recovery
A27: Network transfer included | B27: 100 | C27: 100 | E27: GB — then $0.10/GB overage
A28: Extra branch (per branch-month) | B28: 1.5 | C28: 1.5 | E28: Beyond plan included branches
A30: RENDER PRICING (render.com/docs — current tiers)
A31: Instance Type | B31: Monthly Cost | C31: CPU | D31: RAM | E31: Notes
A32: Free | B32: 0 | C32: 0.1 | D32: 512 MB | E32: Spins down after 15min idle — NOT for production
A33: Starter | B33: 7 | C33: 0.5 | D33: 512 MB | E33: Hobby / background workers
A34: Standard | B34: 25 | C34: 1 | D34: 2 GB | E34: Good starting point for 5 medium clients
A35: Pro | B35: 85 | C35: 2 | D35: 4 GB | E35: When Standard CPU maxes out
A36: Pro Plus | B36: 175 | C36: 4 | D36: 8 GB | E36: High concurrency / heavy queries
A37: Pro Max | B37: 225 | C37: 4 | D37: 16 GB | E37: Memory-intensive workloads
A38: Pro Ultra | B38: 450 | C38: 8 | D38: 32 GB | E38: Enterprise scale
A40: DATABASE SIZE ESTIMATION
A41: Data Category | B41: GB per Company | C41: × Companies | D41: Total GB | E41: Basis
A42: Core data (vehicles, contracts, customers, invoices) | B42: 1.8 | C42: =B6 | D42: =B42*C42 | E42: 275 Prisma models worth of transactional data
A43: TARS fines + Salik historical | B43: 0.5 | C43: =B6 | D43: =B43*C43 | E43: Monthly fine imports accumulate
A44: HR + payroll + attendance | B44: 0.3 | C44: =B6 | D44: =B44*C44 | E44: 50 employees × daily records
A45: Service center + parts inventory | B45: 0.3 | C45: =B6 | D45: =B45*C45 | E45: Work orders, parts catalog
...

Sheet Option A — Starter
A1: OPTION A: Starter Production (~$81/mo)
A2: Best for: First 5 clients onboarding. Neon Launch plan + Render Standard.
A4: NEON — LAUNCH PLAN (Compute)
A5: Component | B5: Value | C5: Unit | D5: Cost | E5: Formula
A6: Average CU size (business hours) | B6: 1 | C6: CU
A7: Average CU size (off-peak) | B7: 0.25 | C7: CU
A8: Business hours/month | B8: =Inputs!B17*Inputs!B18 | C8: hours | E8: =Inputs!B17 hrs × Inputs!B18 days
A9: Off-peak hours/month | B9: =Inputs!B19*Inputs!B18 | C9: hours
A10: Business CU-hours | B10: =B6*B8 | C10: CU-hrs | D10: =B10*Inputs!B24 | E10: CU-hrs × $B24 rate
A11: Off-peak CU-hours | B11: =B7*B9 | C11: CU-hrs | D11: =B11*Inputs!B24
A12: COMPUTE SUBTOTAL | D12: =D10+D11
A14: NEON — LAUNCH PLAN (Storage & Other)
A15: Component | B15: Value | C15: Unit | D15: Cost | E15: Formula
A16: Total storage | B16: =Inputs!D47 | C16: GB | D16: =B16*Inputs!B25
A17: Instant Restore (est. monthly changes) | B17: 5 | C17: GB | D17: =B17*Inputs!B26
A18: Network transfer | B18: < 100 GB included | D18: 0
A19: NEON TOTAL | D19: =D12+D16+D17+D18
A21: RENDER — SERVICES
A22: Service | B22: Instance Type | C22: Instances | D22: Cost | E22: Notes
A23: Backend API (Node + Express + Prisma) | B23: Standard | C23: 1 | D23: =C23*Inputs!B34 | E23: 1 CPU, 2 GB RAM
A24: Frontend (React + Vite) | B24: Static Site | C24: 1 | D24: 0 | E24: Free on Render
A25: Background Worker (TARS, Speed Sync, crons) | B25: Starter | C25: 1 | D25: =C25*Inputs!B33 | E25: 0.5 CPU, 512 MB
A26: RENDER TOTAL | D26: =D23+D24+D25
A28: OPTION A — GRAND TOTAL
A29: Neon (Database) | D29: =D19
A30: Render (Hosting) | D30: =D26
A31: TOTAL PER MONTH | D31: =D19+D26
A32: TOTAL PER YEAR | D32: =D31*12
A33: PER COMPANY / MONTH | D33: =D31/Inputs!B6

Sheet Option B — Growth
A1: OPTION B: Growth Production (~$244/mo)
A2: Best for: 5 active companies using daily. Neon Launch (higher CU) + Render Pro.
A4: NEON — LAUNCH PLAN (Higher Compute)
A5: Component | B5: Value | C5: Unit | D5: Cost | E5: Formula
A6: Average CU size (business hours) | B6: 2 | C6: CU
A7: Average CU size (off-peak) | B7: 0.5 | C7: CU
A8: Business hours/month | B8: =Inputs!B17*Inputs!B18 | C8: hours
A9: Off-peak hours/month | B9: =Inputs!B19*Inputs!B18 | C9: hours
A10: Business CU-hours | B10: =B6*B8 | C10: CU-hrs | D10: =B10*Inputs!B24
A11: Off-peak CU-hours | B11: =B7*B9 | C11: CU-hrs | D11: =B11*Inputs!B24
A12: COMPUTE SUBTOTAL | D12: =D10+D11
A14: NEON — Storage & Other
A15: Component | B15: Value | C15: Unit | D15: Cost
A16: Total storage | B16: =Inputs!D47 | C16: GB | D16: =B16*Inputs!B25
A17: Instant Restore (est. changes) | B17: 8 | C17: GB | D17: =B17*Inputs!B26
A18: NEON TOTAL | D18: =D12+D16+D17
A20: RENDER — SERVICES
A21: Service | B21: Instance Type | C21: Instances | D21: Cost | E21: Notes
A22: Backend API | B22: Pro | C22: 1 | D22: =C22*Inputs!B35
A23: Frontend (Static Site) | B23: Free | D23: 0
A24: Background Worker | B24: Standard | C24: 1 | D24: =C24*Inputs!B34
A25: Team workspace ($19/seat) | B25: Team | C25: 1 | D25: =C25*19
A26: RENDER TOTAL | D26: =D22+D23+D24+D25
A28: OPTION B — GRAND TOTAL
A29: Neon (Database) | D29: =D18
A30: Render (Hosting) | D30: =D26
A31: TOTAL PER MONTH | D31: =D18+D26
A32: TOTAL PER YEAR | D32: =D31*12
A33: PER COMPANY / MONTH | D33: =D31/Inputs!B6

Sheet Option C — Enterprise
A1: OPTION C: Enterprise / SLA (~$671/mo)
A2: Best for: SLA commitments, compliance. Neon Scale plan (always-on) + Render Pro (×2).
A4: NEON — SCALE PLAN (Always-On Compute)
A5: Component | B5: Value | C5: Unit | D5: Cost | E5: Formula
A6: Primary compute (always-on) | B6: 2 | C6: CU
A7: Hours/month (always-on) | B7: 730 | C7: hours | E7: 24 × 30.4 ≈ 730
A8: Primary CU-hours | B8: =B6*B7 | C8: CU-hrs | D8: =B8*Inputs!C24
A9: Read replica (reporting queries) | B9: 0.5 | C9: CU
A10: Replica CU-hours | B10: =B9*B7 | C10: CU-hrs | D10: =B10*Inputs!C24
A11: COMPUTE SUBTOTAL | D11: =D8+D10
A13: NEON — Storage & Other
A14: Component | B14: Value | C14: Unit | D14: Cost
A15: Storage | B15: =Inputs!D47 | C15: GB | D15: =B15*Inputs!B25
A16: Instant Restore (30-day window) | B16: 25 | C16: GB | D16: =B16*Inputs!B26
A17: NEON TOTAL | D17: =D11+D15+D16
A19: RENDER — SERVICES
A20: Service | B20: Instance Type | C20: Instances | D20: Cost | E20: Notes
A21: Backend API (load balanced) | B21: Pro | C21: 2 | D21: =C21*Inputs!B35
A22: Frontend (Static Site) | B22: Free | D22: 0
A23: Background Worker | B23: Standard | C23: 1 | D23: =C23*Inputs!B34
A24: Team workspace ($19/seat × 3) | B24: Team | C24: 3 | D24: =C24*19
A25: RENDER TOTAL | D25: =D21+D22+D23+D24
A27: OPTION C — GRAND TOTAL
A28: Neon (Database) | D28: =D17
A29: Render (Hosting) | D29: =D25
A30: TOTAL PER MONTH | D30: =D17+D25
A31: TOTAL PER YEAR | D31: =D30*12
A32: PER COMPANY / MONTH | D32: =D30/Inputs!B6

Sheet Summary
A1: SIDE-BY-SIDE COMPARISON
A3: Metric | B3: Option A (Starter) | C3: Option B (Growth) | D3: Option C (Enterprise)
A4: Neon (Database) /mo | B4: ='Option A — Starter'!D19 | C4: ='Option B — Growth'!D18 | D4: ='Option C — Enterprise'!D17
A5: Render (Hosting) /mo | B5: ='Option A — Starter'!D26 | C5: ='Option B — Growth'!D26 | D5: ='Option C — Enterprise'!D25
A6: TOTAL / MONTH | B6: ='Option A — Starter'!D31 | C6: ='Option B — Growth'!D31 | D6: ='Option C — Enterprise'!D30
A7: TOTAL / YEAR | B7: ='Option A — Starter'!D31*12 | C7: ='Option B — Growth'!D31*12 | D7: ='Option C — Enterprise'!D30*12
A8: Per Company / Month | B8: ='Option A — Starter'!D31/Inputs!B6 | C8: ='Option B — Growth'!D31/Inputs!B6 | D8: ='Option C — Enterprise'!D30/Inputs!B6
A9: Per Company / Year | B9: ='Option A — Starter'!D31*12/Inputs!B6 | C9: ='Option B — Growth'!D31*12/Inputs!B6 | D9: ='Option C — Enterprise'!D30*12/Inputs!B6
A11: Best for: | B11: Onboarding / MVP | C11: Active daily use | D11: SLA / compliance
A12: Backend tier: | B12: Standard (1 CPU, 2GB) | C12: Pro (2 CPU, 4GB) | D12: Pro ×2 (load balanced)
A13: DB compute: | B13: 1 CU (autoscale) | C13: 2 CU (autoscale) | D13: 2 CU + replica (always-on)
A14: Neon plan: | B14: Launch | C14: Launch | D14: Scale (SOC2, SLA)
A16: 💡 Change any yellow cell on the Inputs sheet and all numbers recalculate.
