Workbook

Sheet Unit Prices
A1: UNIT PRICES — Source of Truth
A2: All yellow cells are editable. Every cost in this workbook = Quantity × Unit Price from this sheet.
A4: NEON RATES (neon.com/docs/introduction/plans — Aug 2025 pricing)
A5: Item | B5: Launch Plan | C5: Scale Plan | E5: Source
A6: Compute (per CU-hour) | B6: 0.106 | C6: 0.222 | E6: CU = ~4 GB RAM + CPU + SSD
A7: Storage (per GB-month) | B7: 0.35 | C7: 0.35 | E7: Actual data size, metered hourly
A8: Instant Restore (per GB-month of changes) | B8: 0.2 | C8: 0.2 | E8: WAL retention for PITR
A9: Public network egress (per GB over 100 GB) | B9: 0.1 | C9: 0.1 | E9: First 100 GB included on paid
A10: Extra branch (per branch-month) | B10: 1.5 | C10: 1.5 | E10: Beyond 10 included (Launch) / 25 (Scale)
A12: RENDER RATES (render.com — current published tiers)
A13: Instance Type | B13: $/month | C13: CPU | D13: RAM (GB) | E13: Notes
A14: Free | B14: 0 | C14: 0.1 | D14: 0.5 | E14: Spins down 15min idle — dev only
A15: Starter | B15: 7 | C15: 0.5 | D15: 0.5 | E15: Background workers, light tasks
A16: Standard | B16: 25 | C16: 1 | D16: 2 | E16: 1 CPU / 2 GB — good baseline
A17: Pro | B17: 85 | C17: 2 | D17: 4 | E17: 2 CPU / 4 GB — medium production
A18: Pro Plus | B18: 175 | C18: 4 | D18: 8 | E18: 4 CPU / 8 GB — high concurrency
A19: Pro Max | B19: 225 | C19: 4 | D19: 16 | E19: 4 CPU / 16 GB — memory heavy
A20: Pro Ultra | B20: 450 | C20: 8 | D20: 32 | E20: 8 CPU / 32 GB — enterprise
A22: NEON CU SIZING REFERENCE
A23: CU Size | B23: RAM | C23: Typical Use
A24: 0.25 | B24: 1 GB | C24: Dev/staging, very light queries
A25: 0.5 | B25: 2 GB | C25: Light production, small working set
A26: 1 | B26: 4 GB | C26: Medium production — 5 tenants baseline
A27: 2 | B27: 8 GB | C27: Active multi-tenant, complex joins
A28: 4 | B28: 16 GB | C28: Heavy reporting + OLTP concurrent

Sheet Data Volume
A1: DATA VOLUME — Records × Row Size = Storage
A2: Estimates per company per year. Based on our 275 Prisma models (schema analysis).
A4: Number of companies | B4: 5
A5: Projection period | B5: 1 | C5: year(s)
A7: RENT-A-CAR MODULE (64 Prisma models — bookings, contracts, vehicles, customers, dispatch)
A8: Table / Data Type | B8: Records/Co/Yr | C8: Avg Row (KB) | D8: GB/Co/Yr | E8: GB Total | F8: Basis
A9: vehicles | B9: 200 | C9: 2.5 | D9: =B9*C9/1024/1024*B5 | E9: =D9*B4 | F9: ~71 fields incl JSON metadata
A10: bookings | B10: 6000 | C10: 1.8 | D10: =B10*C10/1024/1024*B5 | E10: =D10*B4 | F10: ~60 fields, 500/mo × 12
A11: rentalContracts | B11: 4800 | C11: 2.8 | D11: =B11*C11/1024/1024*B5 | E11: =D11*B4 | F11: ~78 fields, 400/mo × 12
A12: customers | B12: 2000 | C12: 2 | D12: =B12*C12/1024/1024*B5 | E12: =D12*B4 | F12: ~59 fields, growing base
A13: deliveries + dispatch | B13: 4800 | C13: 1 | D13: =B13*C13/1024/1024*B5 | E13: =D13*B4 | F13: Delivery slots, tracking logs
A14: deposits + charges | B14: 3000 | C14: 0.5 | D14: =B14*C14/1024/1024*B5 | E14: =D14*B4 | F14: Operational charges per contract
A15: driver profiles + KYC docs | B15: 500 | C15: 1.5 | D15: =B15*C15/1024/1024*B5 | E15: =D15*B4 | F15: Driver + document metadata
A16: vehicle_movements | B16: 12000 | C16: 1.8 | D16: =B16*C16/1024/1024*B5 | E16: =D16*B4 | F16: ~58 fields, plate/status changes
A17: booking_chat + notes | B17: 8000 | C17: 0.8 | D17: =B17*C17/1024/1024*B5 | E17: =D17*B4 | F17: Messages, tags, internal notes
A18: Indexes overhead (this module) | D18: =SUM(D9:D17)*0.4 | E18: =D18*B4 | F18: ~40% of data size
A19: RENT-A-CAR SUBTOTAL | D19: =SUM(D9:D18) | E19: =SUM(E9:E18)
A21: FINANCE MODULE (58 Prisma models — invoices, payments, vouchers, GL, assets)
A22: Table / Data Type | B22: Records/Co/Yr | C22: Avg Row (KB) | D22: GB/Co/Yr | E22: GB Total | F22: Basis
A23: invoices | B23: 6000 | C23: 1.5 | D23: =B23*C23/1024/1024*B5 | E23: =D23*B4 | F23: ~500/mo, linked to contracts
A24: payments | B24: 6000 | C24: 1.2 | D24: =B24*C24/1024/1024*B5 | E24: =D24*B4 | F24: Payment records per invoice
A25: accounting_entries | B25: 15000 | C25: 1 | D25: =B25*C25/1024/1024*B5 | E25: =D25*B4 | F25: ~35 fields, journal entries
A26: receipt_vouchers | B26: 3000 | C26: 1.5 | D26: =B26*C26/1024/1024*B5 | E26: =D26*B4 | F26: ~45 fields
A27: payment_vouchers | B27: 2000 | C27: 1.4 | D27: =B27*C27/1024/1024*B5 | E27: =D27*B4 | F27: ~43 fields
A28: credit_notes | B28: 500 | C28: 1.2 | D28: =B28*C28/1024/1024*B5 | E28: =D28*B4 | F28: ~36 fields
A29: fixed_assets | B29: 100 | C29: 2 | D29: =B29*C29/1024/1024*B5 | E29: =D29*B4 | F29: ~56 fields, depreciation records
A30: transactions + GL | B30: 20000 | C30: 0.8 | D30: =B30*C30/1024/1024*B5 | E30: =D30*B4 | F30: High-volume ledger lines
A31: Indexes overhead (this module) | D31: =SUM(D23:D30)*0.4 | E31: =D31*B4 | F31: ~40% of data size
A32: FINANCE SUBTOTAL | D32: =SUM(D23:D31) | E32: =SUM(E23:E31)
A34: TARS MODULE (2 models — traffic fines + Salik toll charges)
A35: Table / Data Type | B35: Records/Co/Yr | C35: Avg Row (KB) | D35: GB/Co/Yr | E35: GB Total | F35: Basis
A36: tars_fines | B36: 2400 | C36: 1 | D36: =B36*C36/1024/1024*B5 | E36: =D36*B4 | F36: ~19 fields, 200/mo × 12
A37: tars_salik | B37: 6000 | C37: 0.7 | D37: =B37*C37/1024/1024*B5 | E37: =D37*B4 | F37: ~16 fields, toll charges daily
A38: Indexes overhead | D38: =SUM(D36:D37)*0.4 | E38: =D38*B4 | F38: ~40%
A39: TARS SUBTOTAL | D39: =SUM(D36:D38) | E39: =SUM(E36:E38)
A41: HR MODULE (2 models — payroll, salary records)
A42: Table / Data Type | B42: Records/Co/Yr | C42: Avg Row (KB) | D42: GB/Co/Yr | E42: GB Total | F42: Basis
A43: employee_salary_records | B43: 600 | C43: 1.2 | D43: =B43*C43/1024/1024*B5 | E43: =D43*B4 | F43: ~29 fields, 50 emp × 12 months
A44: payroll_cycles | B44: 12 | C44: 1 | D44: =B44*C44/1024/1024*B5 | E44: =D44*B4 | F44: ~27 fields, monthly cycle
A45: attendance + leave (est.) | B45: 15000 | C45: 0.3 | D45: =B45*C45/1024/1024*B5 | E45: =D45*B4 | F45: Daily records × 50 employees
...

Sheet Compute Usage
A1: COMPUTE USAGE — Hours × CU Size × Rate = Cost
A2: Neon bills per CU-hour. More queries or heavier queries = higher CU = higher cost.
A4: TIME INPUTS
A5: Business hours per day | B5: 14 | F5: UAE: ~8am to 10pm
A6: Off-peak hours per day | B6: 10 | F6: 10pm to 8am
A7: Days per month | B7: 30
A8: Business hours/month | B8: =B5*B7
A9: Off-peak hours/month | B9: =B6*B7
A11: OPTION A: STARTER (Neon Launch)
A12: Period | B12: CU Size | C12: Hours | D12: CU-Hours | E12: × Rate | F12: Cost
A13: Business hours (avg load) | B13: 1 | C13: =B8 | D13: =B13*C13 | E13: ='Unit Prices'!B6 | F13: =D13*E13
A14: Off-peak (minimal, before scale-to-zero) | B14: 0.25 | C14: =B9 | D14: =B14*C14 | E14: ='Unit Prices'!B6 | F14: =D14*E14
A15: OPTION A — COMPUTE TOTAL | D15: =D13+D14 | E15: CU-hrs total | F15: =F13+F14
A17: OPTION B: GROWTH (Neon Launch, higher CU)
A18: Period | B18: CU Size | C18: Hours | D18: CU-Hours | E18: × Rate | F18: Cost
A19: Business hours (heavier queries) | B19: 2 | C19: =B8 | D19: =B19*C19 | E19: ='Unit Prices'!B6 | F19: =D19*E19
A20: Off-peak | B20: 0.5 | C20: =B9 | D20: =B20*C20 | E20: ='Unit Prices'!B6 | F20: =D20*E20
A21: OPTION B — COMPUTE TOTAL | D21: =D19+D20 | F21: =F19+F20
A23: OPTION C: ENTERPRISE (Neon Scale, always-on + replica)
A24: Period | B24: CU Size | C24: Hours | D24: CU-Hours | E24: × Rate | F24: Cost
A25: Primary compute (always-on) | B25: 2 | C25: 730 | D25: =B25*C25 | E25: ='Unit Prices'!C6 | F25: =D25*E25
A26: Read replica (reporting) | B26: 0.5 | C26: 730 | D26: =B26*C26 | E26: ='Unit Prices'!C6 | F26: =D26*E26
A27: OPTION C — COMPUTE TOTAL | D27: =D25+D26 | F27: =F25+F26

Sheet Cost Rollup
A1: COST ROLLUP — Every line = Quantity × Unit Price
A2: No lump sums. Change any input on prior sheets and costs recalculate.
A4: OPTION A: STARTER
A5: Line Item | B5: Quantity | C5: Unit | D5: Unit Price | E5: Subtotal | F5: Notes
A6: Neon Compute (Launch) | B6: 1 | C6: lump (see Compute Usage) | E6: ='Compute Usage'!F15 | F6: CU-hours × rate — see Compute Usage sheet
A7: Neon Storage | B7: ='Data Volume'!E62 | C7: GB-month | D7: ='Unit Prices'!B7 | E7: =B7*D7 | F7: From Data Volume sheet
A8: Neon Instant Restore | B8: 5 | C8: GB-month (changes) | D8: ='Unit Prices'!B8 | E8: =B8*D8 | F8: WAL retention for point-in-time recovery
A9: Neon Network Egress (over 100 GB) | B9: 0 | C9: GB over included | D9: ='Unit Prices'!B9 | E9: =B9*D9 | F9: 100 GB included free on paid plans
A10: NEON SUBTOTAL | E10: =E6+E7+E8+E9
A11: Render Backend API | B11: 1 | C11: instance(s) | D11: ='Unit Prices'!B16 | E11: =B11*D11
A12: Render Frontend (Static Site) | B12: 1 | C12: site | D12: 0 | E12: =B12*D12 | F12: Free tier
A13: Render Background Worker | B13: 1 | C13: instance(s) | D13: ='Unit Prices'!B15 | E13: =B13*D13
A14: Render Team Workspace | B14: 0 | C14: seat(s) | D14: 19 | E14: =B14*D14 | F14: $19/seat/mo (0 = Individual plan)
A15: RENDER SUBTOTAL | E15: =E11+E12+E13+E14
A16: OPTION A: STARTER — TOTAL / MONTH | E16: =E10+E15
A17: Total / Year | E17: =E16*12
A18: Per Company / Month | E18: =E16/'Data Volume'!B4
A20: OPTION B: GROWTH
A21: Line Item | B21: Quantity | C21: Unit | D21: Unit Price | E21: Subtotal | F21: Notes
A22: Neon Compute (Launch) | B22: 1 | C22: lump (see Compute Usage) | E22: ='Compute Usage'!F21 | F22: CU-hours × rate — see Compute Usage sheet
A23: Neon Storage | B23: ='Data Volume'!E62 | C23: GB-month | D23: ='Unit Prices'!B7 | E23: =B23*D23 | F23: From Data Volume sheet
A24: Neon Instant Restore | B24: 8 | C24: GB-month (changes) | D24: ='Unit Prices'!B8 | E24: =B24*D24 | F24: WAL retention for point-in-time recovery
A25: Neon Network Egress (over 100 GB) | B25: 0 | C25: GB over included | D25: ='Unit Prices'!B9 | E25: =B25*D25 | F25: 100 GB included free on paid plans
A26: NEON SUBTOTAL | E26: =E22+E23+E24+E25
A27: Render Backend API | B27: 1 | C27: instance(s) | D27: ='Unit Prices'!B17 | E27: =B27*D27
A28: Render Frontend (Static Site) | B28: 1 | C28: site | D28: 0 | E28: =B28*D28 | F28: Free tier
A29: Render Background Worker | B29: 1 | C29: instance(s) | D29: ='Unit Prices'!B16 | E29: =B29*D29
A30: Render Team Workspace | B30: 1 | C30: seat(s) | D30: 19 | E30: =B30*D30 | F30: $19/seat/mo (0 = Individual plan)
A31: RENDER SUBTOTAL | E31: =E27+E28+E29+E30
A32: OPTION B: GROWTH — TOTAL / MONTH | E32: =E26+E31
A33: Total / Year | E33: =E32*12
A34: Per Company / Month | E34: =E32/'Data Volume'!B4
A36: OPTION C: ENTERPRISE
A37: Line Item | B37: Quantity | C37: Unit | D37: Unit Price | E37: Subtotal | F37: Notes
A38: Neon Compute (Scale) | B38: 1 | C38: lump (see Compute Usage) | E38: ='Compute Usage'!F27 | F38: CU-hours × rate — see Compute Usage sheet
A39: Neon Storage | B39: ='Data Volume'!E62 | C39: GB-month | D39: ='Unit Prices'!B7 | E39: =B39*D39 | F39: From Data Volume sheet
A40: Neon Instant Restore | B40: 25 | C40: GB-month (changes) | D40: ='Unit Prices'!B8 | E40: =B40*D40 | F40: WAL retention for point-in-time recovery
A41: Neon Network Egress (over 100 GB) | B41: 0 | C41: GB over included | D41: ='Unit Prices'!B9 | E41: =B41*D41 | F41: 100 GB included free on paid plans
A42: NEON SUBTOTAL | E42: =E38+E39+E40+E41
A43: Render Backend API | B43: 2 | C43: instance(s) | D43: ='Unit Prices'!B17 | E43: =B43*D43
...

Sheet Per Client
A1: PER CLIENT COST ESTIMATE — Companies A through E
A2: Each company has its own fleet size, user count, and data profile. Costs are proportional to usage.
A4: CLIENT PROFILES (edit yellow cells per company)
A5: Metric | B5: Company A | C5: Company B | D5: Company C | E5: Company D | F5: Company E | G5: TOTAL | H5: Notes
A6: Company Name | B6: Al Raha Fleet | C6: Desert Star Rental | D6: Gulf Line Cars | E6: Oasis Motors | F6: Palm Drive LLC | H6: Example names — edit to match actual clients
A7: Fleet size (vehicles) | B7: 120 | C7: 250 | D7: 80 | E7: 300 | F7: 150 | G7: =SUM(B7:F7)
A8: Concurrent users (peak) | B8: 10 | C8: 25 | D8: 8 | E8: 30 | F8: 15 | G8: =SUM(B8:F8)
A9: Contracts / month | B9: 70 | C9: 160 | D9: 45 | E9: 200 | F9: 90 | G9: =SUM(B9:F9) | H9: ~50-70% of fleet, mix of short/long-term
A10: Invoices / month | B10: 85 | C10: 190 | D10: 55 | E10: 240 | F10: 110 | G10: =SUM(B10:F10) | H10: Contracts + extensions + additional charges
A11: TARS fines / month | B11: 80 | C11: 200 | D11: 50 | E11: 250 | F11: 120 | G11: =SUM(B11:F11)
A12: Employees (HR) | B12: 25 | C12: 60 | D12: 15 | E12: 80 | F12: 40 | G12: =SUM(B12:F12)
A13: Customers in DB | B13: 800 | C13: 2000 | D13: 500 | E13: 3000 | F13: 1200 | G13: =SUM(B13:F13)
A15: ESTIMATED STORAGE PER CLIENT (GB) — records × avg row size + 40% index overhead
A16: Data Category | B16: Company A | C16: Company B | D16: Company C | E16: Company D | F16: Company E | G16: TOTAL | H16: Calculation
A17: Vehicles + movements | B17: =(B7*2.5 + B7*12*1.8)/1024/1024 | C17: =(C7*2.5 + C7*12*1.8)/1024/1024 | D17: =(D7*2.5 + D7*12*1.8)/1024/1024 | E17: =(E7*2.5 + E7*12*1.8)/1024/1024 | F17: =(F7*2.5 + F7*12*1.8)/1024/1024 | G17: =SUM(B17:F17) | H17: fleet × 2.5KB + fleet × 12mo × 1.8KB movement
A18: Contracts + bookings | B18: =B9*12*(2.8+1.8)/1024/1024 | C18: =C9*12*(2.8+1.8)/1024/1024 | D18: =D9*12*(2.8+1.8)/1024/1024 | E18: =E9*12*(2.8+1.8)/1024/1024 | F18: =F9*12*(2.8+1.8)/1024/1024 | G18: =SUM(B18:F18) | H18: contracts/mo × 12 × (2.8+1.8) KB per booking+contract
A19: Customers + KYC docs | B19: =(B13*2.0 + B13*0.5*1.5)/1024/1024 | C19: =(C13*2.0 + C13*0.5*1.5)/1024/1024 | D19: =(D13*2.0 + D13*0.5*1.5)/1024/1024 | E19: =(E13*2.0 + E13*0.5*1.5)/1024/1024 | F19: =(F13*2.0 + F13*0.5*1.5)/1024/1024 | G19: =SUM(B19:F19) | H19: customers × 2KB + 50% have docs × 1.5KB
A20: Invoices + payments + GL | B20: =B10*12*(1.5+1.2+3*0.8)/1024/1024 | C20: =C10*12*(1.5+1.2+3*0.8)/1024/1024 | D20: =D10*12*(1.5+1.2+3*0.8)/1024/1024 | E20: =E10*12*(1.5+1.2+3*0.8)/1024/1024 | F20: =F10*12*(1.5+1.2+3*0.8)/1024/1024 | G20: =SUM(B20:F20) | H20: inv/mo × 12 × (1.5 inv + 1.2 pay + 2.4 journal KB)
A21: TARS fines + Salik | B21: =(B11*12*1.0 + B11*2.5*12*0.7)/1024/1024 | C21: =(C11*12*1.0 + C11*2.5*12*0.7)/1024/1024 | D21: =(D11*12*1.0 + D11*2.5*12*0.7)/1024/1024 | E21: =(E11*12*1.0 + E11*2.5*12*0.7)/1024/1024 | F21: =(F11*12*1.0 + F11*2.5*12*0.7)/1024/1024 | G21: =SUM(B21:F21) | H21: fines/mo × 12 × 1KB + salik (2.5× fines) × 0.7KB
A22: HR + payroll + attendance | B22: =(B12*12*1.2 + B12*300*0.3)/1024/1024 | C22: =(C12*12*1.2 + C12*300*0.3)/1024/1024 | D22: =(D12*12*1.2 + D12*300*0.3)/1024/1024 | E22: =(E12*12*1.2 + E12*300*0.3)/1024/1024 | F22: =(F12*12*1.2 + F12*300*0.3)/1024/1024 | G22: =SUM(B22:F22) | H22: emp × 12 salary recs + emp × 300 workdays × 0.3KB attend
A23: Service + Recovery + Admin + Logs | B23: =(B8*2000*0.5)/1024/1024 + 0.3 | C23: =(C8*2000*0.5)/1024/1024 + 0.3 | D23: =(D8*2000*0.5)/1024/1024 + 0.3 | E23: =(E8*2000*0.5)/1024/1024 + 0.3 | F23: =(F8*2000*0.5)/1024/1024 + 0.3 | G23: =SUM(B23:F23) | H23: users × 2000 actions × 0.5KB logs + 0.3GB baseline
A24: Index overhead (40%) | B24: =SUM(B17:B23)*0.4 | C24: =SUM(C17:C23)*0.4 | D24: =SUM(D17:D23)*0.4 | E24: =SUM(E17:E23)*0.4 | F24: =SUM(F17:F23)*0.4 | G24: =SUM(B24:F24) | H24: 628 indexes — ~40% overhead is typical for write-heavy ERP
A25: TOTAL STORAGE (GB) | B25: =SUM(B17:B24) | C25: =SUM(C17:C24) | D25: =SUM(D17:D24) | E25: =SUM(E17:E24) | F25: =SUM(F17:F24) | G25: =SUM(B25:F25)
A27: MONTHLY COST PER CLIENT (Option A: Starter — Neon Launch + Render Standard)
A28: Cost Component | B28: Company A | C28: Company B | D28: Company C | E28: Company D | F28: Company E | G28: TOTAL | H28: How Calculated
A29: Neon Storage | B29: =B25*'Unit Prices'!B7 | C29: =C25*'Unit Prices'!B7 | D29: =D25*'Unit Prices'!B7 | E29: =E25*'Unit Prices'!B7 | F29: =F25*'Unit Prices'!B7 | G29: =SUM(B29:F29) | H29: Client GB × $0.35/GB-month
A30: Neon Compute (by user share) | B30: =(B8/G8)*'Compute Usage'!F15 | C30: =(C8/G8)*'Compute Usage'!F15 | D30: =(D8/G8)*'Compute Usage'!F15 | E30: =(E8/G8)*'Compute Usage'!F15 | F30: =(F8/G8)*'Compute Usage'!F15 | G30: =SUM(B30:F30) | H30: (client users ÷ total users) × total compute cost
A31: Neon Instant Restore | B31: =(B25/G25)*5*'Unit Prices'!B8 | C31: =(C25/G25)*5*'Unit Prices'!B8 | D31: =(D25/G25)*5*'Unit Prices'!B8 | E31: =(E25/G25)*5*'Unit Prices'!B8 | F31: =(F25/G25)*5*'Unit Prices'!B8 | G31: =SUM(B31:F31) | H31: (client storage ÷ total) × 5GB changes × $0.20
A32: Render Backend (by user share) | B32: =(B8/G8)*'Unit Prices'!B16 | C32: =(C8/G8)*'Unit Prices'!B16 | D32: =(D8/G8)*'Unit Prices'!B16 | E32: =(E8/G8)*'Unit Prices'!B16 | F32: =(F8/G8)*'Unit Prices'!B16 | G32: =SUM(B32:F32) | H32: (client users ÷ total) × $25 Standard instance
A33: Render Worker (split evenly) | B33: ='Unit Prices'!B15/5 | C33: ='Unit Prices'!B15/5 | D33: ='Unit Prices'!B15/5 | E33: ='Unit Prices'!B15/5 | F33: ='Unit Prices'!B15/5 | G33: =SUM(B33:F33) | H33: $7 Starter ÷ 5 companies
A34: Render Frontend (split evenly) | B34: 0 | C34: 0 | D34: 0 | E34: 0 | F34: 0 | G34: 0 | H34: Static site = free
A35: TOTAL COST / MONTH | B35: =B29+B30+B31+B32+B33+B34 | C35: =C29+C30+C31+C32+C33+C34 | D35: =D29+D30+D31+D32+D33+D34 | E35: =E29+E30+E31+E32+E33+E34 | F35: =F29+F30+F31+F32+F33+F34 | G35: =SUM(B35:F35)
A36: TOTAL COST / YEAR | B36: =B35*12 | C36: =C35*12 | D36: =D35*12 | E36: =E35*12 | F36: =F35*12 | G36: =SUM(B36:F36)
A38: COST SHARE (%) — who's using what portion of the infrastructure
A39: Metric | B39: Company A | C39: Company B | D39: Company C | E39: Company D | F39: Company E | G39: TOTAL
A40: % of total cost | B40: =B35/G35 | C40: =C35/G35 | D40: =D35/G35 | E40: =E35/G35 | F40: =F35/G35 | G40: =SUM(B40:F40)
A41: % of storage | B41: =B25/G25 | C41: =C25/G25 | D41: =D25/G25 | E41: =E25/G25 | F41: =F25/G25 | G41: =SUM(B41:F41)
A42: % of compute (by users) | B42: =B8/G8 | C42: =C8/G8 | D42: =D8/G8 | E42: =E8/G8 | F42: =F8/G8 | G42: =SUM(B42:F42)
A44: 💡 Edit the yellow profile cells above to match real client data. Storage, compute share, and costs all recalculate.
